# 一、 `Java` 异常处理

在 Java 中，异常处理是一种重要的编程概念，用于处理程序执行过程中可能出现的错误或异常情况。

异常是程序中的一些错误，但并不是所有的错误都是异常，并且错误有时候是可以避免的。

比如说，你的代码少了一个分号，那么运行出来结果是提示是错误 `java.lang.Error`，如果你用 `System.out.println(11/0)`，那么你是因为你用 **0** 做了除数，会抛出 `java.lang.ArithmeticException` 的异常。 

异常发生的原因有很多，通常包含以下几大类：

- 用户输入了非法数据。
- 要打开的文件不存在。
- 网络通信时连接中断，或者 `JVM` 内存溢出。

这些异常有的是因为用户错误引起，有的是程序错误引起的，还有其它一些是因为物理错误引起的。

要理解 Java 异常处理是如何工作的，你需要掌握**以下三种类型的异常**：

1. **检查性异常：**最具代表的检查性异常是**用户错误或问题**引起的异常，这些异常在**编译时强制要求程序员处理**。例如要打开一个不存在文件时，一个异常就发生了，这些异常在编译时不能被简单地忽略。这类异常通常**使用 try-catch 块来捕获并处理异常**，或者**在方法声明中使用 throws 子句声明方法可能抛出的异常**。

```java
try {
    // 可能会抛出异常的代码
} catch (IOException e) {
    // 处理异常的代码
}
```

或者：

```java
public void readFile() throws IOException {
    // 可能会抛出IOException的代码
}
```

2. **运行时异常：** 一些异常在编译时不强制要求处理，通常是由程序中的错误引起的，例如 `NullPointerException`、`ArrayIndexOutOfBoundsException` 等，这类异常可以选择处理，但并非强制要求。

```java
try {
    // 可能会抛出异常的代码
} catch (NullPointerException e) {
    // 处理异常的代码
}
```

3. **错误：** 错误不是异常，而是脱离程序员控制的问题，错误在代码中通常被忽略。例如，当栈溢出时，一个错误就发生了，它们**在编译也检查不到**的。

Java 提供了以下关键字和类来支持异常处理：

- **try**：用于包裹可能会抛出异常的代码块。
- **catch**：用于捕获异常并处理异常的代码块。
- **finally**：用于包含无论是否发生异常都需要执行的代码块。
- **throw**：用于手动抛出异常。
- **throws**：用于在方法声明中指定方法可能抛出的异常。
- **Exception**类：是所有异常类的父类，它提供了一些方法来获取异常信息，如 **`getMessage()`、`printStackTrace()`** 等。

# 二、Exception 类的层次

所有的异常类是从 `java.lang.Exception` 类继承的子类。

Exception 类是 `Throwable` 类的子类。除了Exception类外，`Throwable` 还有一个子类Error 。

**Java 程序通常不捕获错误**。错误一般发生在严重故障时，它们在Java程序处理的范畴之外。**Error 用来指示运行时环境发生的错误**。例如，`JVM` 内存溢出。**一般地，程序不会从错误中恢复**。

异常类有两个主要的子类：`IOException` 类和 `RuntimeException` 类。

![img](20.Java 异常处理.assets/exception-hierarchy.png)

在 Java 内置类中(接下来会说明)，有大部分常用检查性和非检查性异常。

# 三、Java 内置异常类

Java 语言定义了一些异常类在 `java.lang` 标准包中。

标准运行时异常类的子类是最常见的异常类。由于 **`java.lang` 包是默认加载到所有的 Java 程序的**，所以大部分从运行时异常类继承而来的异常都可以直接使用。

Java 根据各个类库也定义了一些其他的异常，下面的表中列出了 Java 的**非检查性异常**。 

|            **异常**             | **描述**                                                     |
| :-----------------------------: | :----------------------------------------------------------- |
|       ArithmeticException       | 当出现异常的运算条件时，抛出此异常。例如，一个整数"除以零"时，抛出此类的一个实例。 |
| ArrayIndexOutOfBoundsException  | 用非法索引访问数组时抛出的异常。如果索引为负或大于等于数组大小，则该索引为非法索引。 |
|       ArrayStoreException       | 试图将错误类型的对象存储到一个对象数组时抛出的异常。         |
|       ClassCastException        | 当试图将对象强制转换为不是实例的子类时，抛出该异常。         |
|    IllegalArgumentException     | 抛出的异常表明向方法传递了一个不合法或不正确的参数。         |
|  IllegalMonitorStateException   | 抛出的异常表明某一线程已经试图等待对象的监视器，或者试图通知其他正在等待对象的监视器而本身没有指定监视器的线程。 |
|      IllegalStateException      | 在非法或不适当的时间调用方法时产生的信号。换句话说，即 Java 环境或 Java 应用程序没有处于请求操作所要求的适当状态下。 |
|   IllegalThreadStateException   | 线程没有处于请求操作所要求的适当状态时抛出的异常。           |
|    IndexOutOfBoundsException    | 指示某排序索引（例如对数组、字符串或向量的排序）超出范围时抛出。 |
|   NegativeArraySizeException    | 如果应用程序试图创建大小为负的数组，则抛出该异常。           |
|      NullPointerException       | 当应用程序试图在需要对象的地方使用 `null` 时，抛出该异常     |
|      NumberFormatException      | 当应用程序试图将字符串转换成一种数值类型，但该字符串不能转换为适当格式时，抛出该异常。 |
|        SecurityException        | 由安全管理器抛出的异常，指示存在安全侵犯。                   |
| StringIndexOutOfBoundsException | 此异常由 `String` 方法抛出，指示索引或者为负，或者超出字符串的大小。 |
|  UnsupportedOperationException  | 当不支持请求的操作时，抛出该异常。                           |

下面的表中列出了 Java 定义在 `java.lang` 包中的**检查性异常类**。

| **异常**                   | **描述**                                                     |
| -------------------------- | ------------------------------------------------------------ |
| ClassNotFoundException     | 应用程序试图加载类时，找不到相应的类，抛出该异常。           |
| CloneNotSupportedException | 当调用 `Object` 类中的 `clone` 方法克隆对象，但该对象的类无法实现 `Cloneable` 接口时，抛出该异常。 |
| IllegalAccessException     | 拒绝访问一个类的时候，抛出该异常。                           |
| InstantiationException     | 当试图使用 `Class` 类中的 `newInstance` 方法创建一个类的实例，而指定的类对象因为是一个接口或是一个抽象类而无法实例化时，抛出该异常。 |
| InterruptedException       | 一个线程被另一个线程中断，抛出该异常。                       |
| NoSuchFieldException       | 请求的变量不存在                                             |
| NoSuchMethodException      | 请求的方法不存在                                             |

# 四、异常方法

下面的列表是 `Throwable` 类的主要方法:

| **序号** | **方法及说明**                                               |
| -------- | ------------------------------------------------------------ |
| 1        | **public String getMessage()**  			返回关于发生的异常的详细信息。这个消息在 `Throwable` 类的构造函数中初始化了。 |
| 2        | **public Throwable getCause()**  			返回一个 Throwable 对象代表异常原因。 |
| 3        | **public String toString()**  			返回此 Throwable 的简短描述。 |
| 4        | **public void printStackTrace()**  			将此 Throwable 及其回溯打印到标准错误流。 |
| 5        | **public StackTraceElement [] getStackTrace()**  			返回一个包含堆栈层次的数组。下标为0的元素代表栈顶，最后一个元素代表方法调用堆栈的栈底。 |
| 6        | **public Throwable fillInStackTrace()**  			用当前的调用栈层次填充Throwable 对象栈层次，添加到栈层次任何先前信息中。 |

# 五、捕获异常

使用 **try 和 catch 关键字**可以捕获异常。try/catch 代码块放在异常可能发生的地方。

try/catch 代码块中的代码称为**保护代码**，使用 try/catch 的语法如下：

```java
try
{
   // 程序代码(保护代码)
}catch(ExceptionName e1)
{
   //Catch 块
}
```

Catch 语句包含要**捕获异常类型的声明**。**当保护代码块中发生一个异常时，try 后面的 catch 块就会被检查。**

如果发生的异常包含在 catch 块中，**异常会被传递到该 catch 块**，这**和传递一个参数的方法是一样**。

**实例**

下面的例子中声明有两个元素的一个数组，当代码试图访问数组的第四个元素的时候（数组越界访问）就会抛出一个异常。

```java
// 文件名 : ExcepTest.java
import java.io.*;
public class ExcepTest{
 
   public static void main(String args[]){
      try{
         int a[] = new int[2];
         System.out.println("Access element three :" + a[3]);
      }catch(ArrayIndexOutOfBoundsException e){
         System.out.println("Exception thrown  :" + e);
      }
      System.out.println("Out of the block");
   }
}
```

以上代码编译运行输出结果如下：

```
Exception thrown  :java.lang.ArrayIndexOutOfBoundsException: 3
Out of the block
```

## 5.1 多重捕获块

一个 try 代码块后面跟随多个 catch 代码块的情况就叫多重捕获。

多重捕获块的语法如下所示：

```java
try{
   // 程序代码
}catch(异常类型1 异常的变量名1){
  // 程序代码
}catch(异常类型2 异常的变量名2){
  // 程序代码
}catch(异常类型3 异常的变量名3){
  // 程序代码
}
```

上面的代码段包含了 3 个 catch块。

可以在 try 语句后面添加任意数量的 catch 块。

如果**保护代码中发生异常，异常被抛给第一个 catch 块**。

如果抛出异常的数据类型与 `ExceptionType1` 匹配，它在这里就会被捕获。

如果**不匹配，它会被传递给第二个 catch 块**。

如此，直到**异常被捕获**或者**通过所有的 catch 块**。

**实例**

该实例展示了怎么使用多重 try/catch。

```java
try {
    file = new FileInputStream(fileName);
    x = (byte) file.read();
} catch(FileNotFoundException f) { // Not valid!
    f.printStackTrace();
    return -1;
} catch(IOException i) {
    i.printStackTrace();
    return -1;
}
```

# 六、throws/throw 关键字

在 Java 中， throw 和 throws 关键字是用于处理异常的。

**throw 关键字**用于**在代码中抛出异常**，而 **throws 关键字**用于**在方法声明中指定可能会抛出的异常类型**。

## 6.1 throw 关键字

`throw` 关键字用于在当前方法中抛出一个异常。

通常情况下，当**代码执行到某个条件下无法继续正常执行时，可以使用 throw 关键字抛出异常，以告知调用者当前代码的执行状态。**

例如，下面的代码中，在方法中判断 `num` 是否小于 0，如果是，则抛出一个 `IllegalArgumentException` 异常。

```java
public void checkNumber(int num) {
  if (num < 0) {
    throw new IllegalArgumentException("Number must be positive");
  }
}
```

## 6.2 throws 关键字

throws 关键字用于**在方法声明中指定该方法可能抛出的异常**。当方法内部**抛出指定类型的异常时**，该**异常会被传递给调用该方法的代码**，并在该代码中处理异常。

例如，下面的代码中，当 `readFile` 方法内部发生 `IOException` 异常时，会将该异常传递给调用该方法的代码。在**调用该方法的代码中，必须捕获或声明处理 `IOException` 异常。**

```java
public void readFile(String filePath) throws IOException {
  BufferedReader reader = new BufferedReader(new FileReader(filePath));
  String line = reader.readLine();
  while (line != null) {
    System.out.println(line);
    line = reader.readLine();
  }
  reader.close();
}
```

**一个方法可以声明抛出多个异常**，**多个异常之间用逗号隔开**。

例如，下面的方法声明抛出 `RemoteException` 和 `InsufficientFundsException`：

```java
import java.io.*;
public class className
{
   public void withdraw(double amount) throws RemoteException,
                              InsufficientFundsException
   {
       // Method implementation
   }
   //Remainder of class definition
}
```

# 七、finally 关键字

`finally` 关键字用来**创建在 `try` 代码块后面执行的代码块**。

**无论是否发生异常**，**`finally` 代码块中的代码总会被执行**。

在 `finally` 代码块中，可以**运行清理类型等收尾善后性质的语句**。

`finally` 代码块**出现在 `catch` 代码块最后**，语法如下：

```java
try{
  // 程序代码
}catch(异常类型1 异常的变量名1){
  // 程序代码
}catch(异常类型2 异常的变量名2){
  // 程序代码
}finally{
  // 程序代码
}
```

```java
public class ExcepTest{
  public static void main(String args[]){
    int a[] = new int[2];
    try{
       System.out.println("Access element three :" + a[3]);
    }catch(ArrayIndexOutOfBoundsException e){
       System.out.println("Exception thrown  :" + e);
    }
    finally{
       a[0] = 6;
       System.out.println("First element value: " +a[0]);
       System.out.println("The finally statement is executed");
    }
  }
}
```

以上实例编译运行结果如下：

```
Exception thrown  :java.lang.ArrayIndexOutOfBoundsException: 3
First element value: 6
The finally statement is executed
```

注意下面事项：

- catch 不能独立于 try 存在。
- 在 try/catch 后面添加 finally 块并非强制性要求的。
- **try 代码后不能既没 catch 块也没 finally 块**。
- **try, catch, finally 块之间不能添加任何代码**。

# 八、try-with-resources

JDK7 之后，Java 新增的 try-with-resource 语法结构，旨在自动管理资源，确保资源在使用后能够及时关闭，避免资源泄露 。

try-with-resources 是一种异常处理机制，它能够**自动关闭在 try 块中声明的资源，无需显式地在 finally 块中关闭。**

在 try-with-resources 语句中，你只需要**在 try 关键字后面声明资源**，然后跟随一个代码块。**无论代码块中的操作是否成功，资源都会在 try 代码块执行完毕后自动关闭。**

```java
try (resource declaration) {
  // 使用的资源
} catch (ExceptionType e1) {
  // 异常块
}
```

以上的语法中 try 用于**声明和实例化资源**，catch 用于**处理关闭资源时可能引发的所有异常**。

```java
import java.io.*;

public class RunoobTest {

    public static void main(String[] args) {
    String line;
        try(BufferedReader br = new BufferedReader(new FileReader("test.txt"))) {
            while ((line = br.readLine()) != null) {
                System.out.println("Line =>"+line);
            }
        } catch (IOException e) {
            System.out.println("IOException in try block =>" + e.getMessage());
        }
    }
}
```

因为实际上没有这个文件，因此以上实例输出结果为：

```
IOException in try block =>test.txt (No such file or directory)
```

再看下不使用 **try-with-resources** 而改成 **finally** 来关闭资源，整体代码量多了很多，而且更复杂繁琐了：

```java
import java.io.*;

class RunoobTest {
    public static void main(String[] args) {
        BufferedReader br = null;
        String line;

        try {
            System.out.println("Entering try block");
            br = new BufferedReader(new FileReader("test.txt"));
            while ((line = br.readLine()) != null) {
            	System.out.println("Line =>"+line);
            }
        } catch (IOException e) {
            System.out.println("IOException in try block =>" + e.getMessage());
        } finally {
            System.out.println("Entering finally block");
            try {
                if (br != null) {
                    br.close();
                }
            } catch (IOException e) {
                System.out.println("IOException in finally block =>"+e.getMessage());
            }
        }
    }
}
```

以上实例输出结果为：

```
Entering try block
IOException in try block =>test.txt (No such file or directory)
Entering finally block
```

## 8.1 try-with-resources 处理多个资源

try-with-resources 语句中**可以声明多个资源**，方法是**使用分号 ; 分隔各个资源**：

```java
import java.io.*;
import java.util.*;
class RunoobTest {
    public static void main(String[] args) throws IOException{
        try (Scanner scanner = new Scanner(new File("testRead.txt")); 
            PrintWriter writer = new PrintWriter(new File("testWrite.txt"))) {
            while (scanner.hasNext()) {
                writer.print(scanner.nextLine());
            }
        }
    }
}
```

以上实例使用 Scanner 对象从 testRead.txt 文件中读取一行并将其写入新的 testWrite.txt 文件中。

多个声明资源时，`try-with-resources` 语句**以相反的顺序关闭这些资源**。 在本例中，**`PrintWriter` 对象先关闭，然后 `Scanner` 对象关闭**。

# 九、声明自定义异常

在 Java 中你可以自定义异常。编写自己的异常类时需要记住下面的几点。

- 所有异常都必须是 Throwable 的子类。
- 如果希望写一个**检查性异常类**，则需要继承 `Exception` 类。
- 如果你想写一个**运行时异常类**，那么需要继承 `RuntimeException` 类。

可以像下面这样定义自己的异常类：

```java
class MyException extends Exception{
}
```

只继承Exception 类来创建的异常类是检查性异常类。

下面的 `InsufficientFundsException` 类是用户定义的异常类，它继承自 Exception。

**一个异常类和其它任何类一样，包含有变量和方法**。

**实例**

以下实例是一个银行账户的模拟，通过银行卡的号码完成识别，可以进行存钱和取钱的操作。

```java
// 文件名InsufficientFundsException.java(异常类定义)
import java.io.*;
 
//自定义异常类，继承Exception类
public class InsufficientFundsException extends Exception
{
  //此处的amount用来储存当出现异常（取出钱多于余额时）所缺乏的钱
  private double amount;
  public InsufficientFundsException(double amount)
  {
    this.amount = amount;
  } 
  public double getAmount()
  {
    return amount;
  }
}
```

为了展示如何使用我们自定义的异常类，

在下面的 `CheckingAccount` 类中包含一个 `withdraw()` 方法抛出一个 `InsufficientFundsException` 异常。

```java
// 文件名称 CheckingAccount.java
import java.io.*;
 
//此类模拟银行账户
public class CheckingAccount
{
  //balance为余额，number为卡号
   private double balance;
   private int number;
   public CheckingAccount(int number)
   {
      this.number = number;
   }
  //方法：存钱
   public void deposit(double amount)
   {
      balance += amount;
   }
  //方法：取钱
   public void withdraw(double amount) throws
                              InsufficientFundsException
   {
      if(amount <= balance)
      {
         balance -= amount;
      }
      else
      {
         double needs = amount - balance;
         throw new InsufficientFundsException(needs);  // 抛出异常
      }
   }
  //方法：返回余额
   public double getBalance()
   {
      return balance;
   }
  //方法：返回卡号
   public int getNumber()
   {
      return number;
   }
}
```

下面的 `BankDemo` 程序示范了如何调用 `CheckingAccount` 类的 deposit() 和 withdraw() 方法。

```java
//文件名称 BankDemo.java
public class BankDemo
{
   public static void main(String [] args)
   {
      CheckingAccount c = new CheckingAccount(101);
      System.out.println("Depositing $500...");
      c.deposit(500.00);
      try
      {
         System.out.println("\nWithdrawing $100...");
         c.withdraw(100.00);
         System.out.println("\nWithdrawing $600...");
         c.withdraw(600.00);    // 此处出现异常
      }catch(InsufficientFundsException e)   // 捕获异常并处理
      {
         System.out.println("Sorry, but you are short $"
                                  + e.getAmount());
         e.printStackTrace();   // 打印错误栈信息
      }
    }
}
```

编译上面三个文件，并运行程序 `BankDemo`，得到结果如下所示：

```
Depositing $500...

Withdrawing $100...

Withdrawing $600...
Sorry, but you are short $200.0
InsufficientFundsException
        at CheckingAccount.withdraw(CheckingAccount.java:25)
        at BankDemo.main(BankDemo.java:13)
```

# 十、异常处理的最佳实践

- 在合适的位置捕获异常，并对异常进行适当的处理，以确保程序的稳定性和可靠性。
- 避免过度捕获异常，应该尽量精确捕获特定类型的异常。
- 使用finally块来释放资源，例如关闭文件或数据库连接等，以确保资源的正确释放。
- 优先处理受检异常，避免将**受检异常**转换为**非受检异常**。